= finally statement (finally 문)
 
* try-catch 예외 처리 문에서 예외의 발생 여부와 상관없이 무조건 실행됨
* 예외 발생시에도 반드시 실행되어야 하는 구문들을 처리할 때 사용

[source, java]
----
public int getMinute(int number) throws DateTimeException {
    …
}
----

---

제어 흐름의 과정과 상관없이 실행해야 하는 코드를 위해 `finally` 절을 사용할 수 있습니다. 제어 흐름이 `try` 블록의 끝이 도달하여 정상적인 실행의 결과로 `try` 블록을 벗어나면 `finally` 블록의 코드가 실행됩니다. 또한 `throw`, `break`, `continue` 문 등으로 제어가 `try` 문을 벗어나면 `finally` 블록의 코드가 실행됩니다.

`finally` 절은 코드의 중복을 방지하고 예외가 발생한 후 리소스를 해제해야 하는 두 가지 상황에서 사용됩니다. 

== 중복 코드 방지

`try` 블록과 `catch` 문 모두에서 반드시 사용되어야 하는 코드가 있는 경우 finally 블록으로 이동시켜 중복을 방지할 수 있습니다. 아래와 같은 코드가 있다면,

[source, java]
----
try {
    …
    statements
}
catch {
    statements
}
----

이를 아래와 같이 단순화할 수 있습니다.

[source, java]
----
try {
    …
}
catch {
    …
}
finally {
    statements
}
----

finally 블록에서 발생하는 예외 역시 try-catch 문으로 처리할 수 있습니다.

[source, java]
----
try {
    …
    try {
        …
    }
    catch (IOException e) {
        // FileNotFoundException이 처리되지 않은 경우
    }
    finally {
        throw new FileNotFoundException(fileName);
        }
    } 
catch (FileNotFoundException e) { 
    // FileNotFoundException이 처리됨 
}
----

`finally` 블록을 실행하는 동안 예외가 발생하고 다른 예외를 던지고 있는 상황에서는 `finally` 블록에서 발생된 예외 이외에는 모두 무시됩니다.

[source, java]
----
try { 
    int i = Integer.parseInt(args[0]);
    throw new Exception("something wrong");  // 손실됨
} 
catch (ArithmeticException e) { 		
    throw new Exception("something wrong 2"); // 손실됨
}
finally {
    throw new ArithmeticException("Wrong number");
}
----

link:./27_exception_method.adoc[이전: 메소드에 예외 선언] +
link:./29_try_with_resource.adoc[다음: try-with-resource clause (try-with-resource 절)]